---
# This wierdness is because with_sequence evaluates and fails even when this task is not executed
# bug closed as a wont_fix by ansible
- name: add nics
  block:
    - community.vmware.vmware_guest_network:
        hostname: "{{ vcenter_address }}"
        username: "{{ vcenter_username }}"
        password: "{{ vcenter_password }}"
        validate_certs: no
        # datacenter: "{{ vcenter_datacenter }}"
        name: '{{ vm_name }}'
        state: present
        force: yes
        device_type:  "e1000"
        network_name: "{{ data_network }}"
        connected: true
        start_connected: true
      delegate_to: localhost
      with_sequence: start=5 end="{{ vm_num_nics }}" 
      ignore_errors: true
  when: vm_num_nics|int > 4
